---
title: Класс Exception и его свойства
ms.date: 03/30/2017
ms.technology: dotnet-standard
helpviewer_keywords:
- exceptions, Exception class
- Exception class
ms.assetid: e2e1f8c4-e7b4-467d-9a66-13c90861221d
author: mairaw
ms.author: mairaw
ms.openlocfilehash: e17fa07fe2dd19cdcd03bc923940abfef886219c
ms.sourcegitcommit: 17ee6605e01ef32506f8fdc686954244ba6911de
ms.translationtype: HT
ms.contentlocale: ru-RU
ms.lasthandoff: 11/21/2019
ms.locfileid: "74283126"
---
# <a name="exception-class-and-properties"></a>Класс и свойства исключений

<xref:System.Exception> — это базовый класс, от которого наследуются исключения. Например, иерархия класса <xref:System.InvalidCastException> имеет следующий вид:

<xref:System.Object>\
&nbsp;&nbsp;<xref:System.Exception>\
&nbsp;&nbsp;&nbsp;&nbsp;<xref:System.SystemException>\
&nbsp;&nbsp;&nbsp;&nbsp;&nbsp;&nbsp;<xref:System.InvalidCastException>

Класс <xref:System.Exception> имеет следующие свойства, которые облегчают анализ исключения.

| Имя свойства | ОПИСАНИЕ |
| ------------- | ----------- |
| <xref:System.Exception.Data> | Свойство <xref:System.Collections.IDictionary>, которое содержит произвольные данные в парах "ключ–значение". |
| <xref:System.Exception.HelpLink> | Может содержать URL-адрес (или URN) файла справки, который предоставляет подробные сведения о причине возникновения исключения. |
| <xref:System.Exception.InnerException> | Это свойство может использоваться для создания и сохранения последовательностей исключений во время обработки исключений. Его можно использовать для создания нового исключения, содержащего ранее перехваченные исключения. Исходное исключение может быть перехвачено вторым исключением в свойстве <xref:System.Exception.InnerException>, что позволяет коду, обрабатывающему второе исключение, проверить дополнительные данные. Например, предположим, что у вас есть метод, который принимает аргумент в неправильном формате.  Код пытается считать аргумент, но создается исключение. Метод перехватывает исключение и выдает <xref:System.FormatException>. Чтобы расширить возможности вызывающего объекта для определения причины исключения, иногда желательно, чтобы метод перехватывал исключение, выданное вспомогательной процедурой, а затем выдавал исключение, содержащее больше сведений о возникшей ошибке. Можно создать новое и более информативное исключение, где ссылка на внутреннее исключение может указывать на исходное исключение. Затем это более информативное исключение может выдаваться вызывающему объекту. Обратите внимание, что с помощью данной функции можно создать последовательность связанных исключений, которая завершается первым выданным исключением. |
| <xref:System.Exception.Message> | Предоставляет сведения о причине возникновения исключения.
| <xref:System.Exception.Source> | Возвращает или задает имя приложения или объекта, вызывавшего ошибку. |
| <xref:System.Exception.StackTrace>| Содержит трассировку стека, которую можно использовать для определения места возникновения ошибки. Эта трассировка стека содержит имя исходного файла и, при наличии отладочной информации, номер программной строки. |

Большинство классов, унаследованных от <xref:System.Exception>, не реализуют дополнительные элементы и не предоставляют дополнительные функции. Они просто наследуются от <xref:System.Exception>. Таким образом, наиболее важные сведения для исключения можно найти в иерархии классов исключений, имени исключения и информации, содержащейся в самом исключении.

Мы рекомендуем создавать и перехватывать только те объекты, которые являются производными от <xref:System.Exception>, но в качестве исключения можно создать любой объект, производный от класса <xref:System.Object>. Обратите внимание, что не все языки поддерживают создание и перехват объектов, не являющихся производными от <xref:System.Exception>.
  
## <a name="see-also"></a>См. также

- [Исключения](index.md)
